Workbook

Sheet Read me first
B7: This particular database is Mega Multisite Churches throughout North America
B9: Information is updated by going to the oldest information, cleaning, updating and moving to the next oldest
B11: If you see cells that have no information please note it will once a updat of that state is posted
B13: Obviously information can vary and we have a COVID disclaimer.
B14: After COVID information from churches has chnaged dramatically
B15: Some of the more notable changes, is a downsizing (attendance, staff, multisite locations, etc)
B17: This database is one of many databses Connected Churches has
B19: Other Databases of Interest (some of the more requested)
D20: Total | E20: Total
D21: Staff | E21: Churches
B22: Assembly of God | D22: 52203 | E22: 26560
B23: Foursquare | D23: 4454 | E23: 1558
B24: ECO | D24: 401 | E24: 3026
B25: Southern Baptist (12 states and growing) | D25: 5391 | E25: 2371

Sheet Executive Summary
B3: Executive Summary
B5: Mega Churches
B6: (Multiple denomination's)
B8: States | C8: 58 | D8: Including Canada
B9: Churches | C9: =SUM('State by State'!F65) -> 2403
B10: Senior Leadership | C10: =SUM('State by State'!AR65) -> 3814
B11: All Staff | C11: =SUM('State by State'!E65) -> 64032
B12: Emails | C12: =SUM('State by State'!CG65:CH65) -> 47116
B13: Total Impressions | C13: =SUM('State by State'!CK76) -> 32270001 | D13: Impressions that you might be able to get access to
D14: Email accounts, followers (twitter/instagram/other media),
D15: friends (facebook), blogs, etc

Sheet State by State
B2: This data is from Mega and Multisite Churches in North America
B3: Built by Connected Churches
B4: Key information/legend at the bottom
C6: CONTACTS | R6: INFLUENCE | AB6: LEAD PASTORS | AJ6: EXECUTIVE TEAMS | AR6: POSITIONS | BJ6: SIZE | BW6: GROWTH | CF6: COMMUNICATIONS
C7: Young | D7: Young | F7: Total | H7: Staffing | R7: Other Area's of Influence | Z7: Mail | AB7: Lead Pastor | AJ7: By Sr Leadership (Campus, Teaching & Executive) | AR7: By position type | BJ7: By Size | BQ7: Outreach Mag | BT7: Total | BU7: Total | BW7: Multisite by category | CF7: 75% of staff | CG7: Social Media
C8: (mid 40's younger) | D8: (mid 40's younger) | E8: Total | F8: Mega | H8: Size of Individual Church Staff | R8: Do they host | T8: Written | U8: On-Site | V8: Radio/TV | W8: Network | X8: Other | Y8: My | Z8: ARC | AB8: Race | AJ8: Race | AR8: Sr Ldrshp | AS8: Campus | AT8: Teaching | AU8: Executive | AV8: Pastoral Care | AW8: Unknown | AX8: Administration | BA8: Jr/Sr | BB8: College/Young | BC8: Community/ | BD8: Worship | BF8: Comm/Mrktg | BH8: Outreach/ | BJ8: Attendance Range | BQ8: Largest | BR8: Fastest | BT8: Mega | BU8: Multisite | BW8: Qty 2-4 | BX8: Qty 5-9 | BY8: Qty 10-14 | BZ8: 15+ | CA8: Different | CB8: Campuses in | CC8: Intl | CD8: Campuses in | CF8: list their | CG8: Email 1 | CH8: Email 2 | CI8: Twitter | CJ8: Twitter | CK8: Twitter | CL8: Facebook | CM8: Facebook | CO8: Instagram | CP8: Instagram | CQ8: Other | CR8: Other
B9: State | C9: Lead Pastor | D9: Staff | E9: Staff | F9: Churches | H9: Qty 1-5 | I9: Qty 6-10 | J9: Qty 11-19 | K9: 20-49 | L9: 50-99 | M9: 100-199 | N9: 200-299 | O9: 300-399 | P9: 400+ | R9: conferences | S9: Podcast | T9: Multiple Books | U9: Book store | V9: Reach | W9: Leader | X9: Misc | Y9: Top 10 | Z9: Copy | AB9: White | AC9: Black | AD9: Latino | AE9: Asian | AF9: Unknown | AG9: Other | AH9: Woman | AJ9: White | AK9: Black | AL9: Latino | AM9: Asian | AN9: Unknown | AO9: Other | AP9: Woman | AR9: Team | AS9: Pastors | AT9: Pastors | AU9: Pastor | AV9: Counseling | AW9: Asst/Associate | AX9: Operations | AY9: Women's | AZ9: Children's | BA9: High | BB9: Adults/Interns | BC9: Groups | BD9: Pstrs/Ldrs | BE9: AVL-Stage | BF9: Creative | BG9: Men | BH9: Missions | BJ9: 0-999 | BK9: 1-2k | BL9: 2-3k | BM9: 3-5k | BN9: 5-9k | BO9: 10k+ | BP9: Unknown | BQ9: Church | BR9: Church | BT9: Churches | BU9: churches | BW9: Campuses | BX9: Campuses | BY9: Campuses | BZ9: Campuses | CA9: State | CB9: State(s) | CC9: Campus | CD9: Countries | CF9: social media | CG9: Qty | CH9: Qty | CI9: Talkers | CJ9: Qty | CK9: Followers | CL9: Qty | CM9: Friends | CN9: Blogs | CO9: Qty | CP9: Followers | CQ9: Media | CR9: Followers
B10: Alabama | C10: 15 | D10: 667 | E10: 1761 | F10: 54 | H10: 3 | I10: 9 | J10: 13 | K10: 22 | L10: 8 | M10: 1 | N10: 1 | O10: 0 | P10: 0 | R10: 1 | T10: 1 | U10: 1 | V10: 1 | W10: 2 | X10: 1 | Y10: 7 | Z10: 4 | AB10: 49 | AC10: 8 | AD10: 0 | AE10: 0 | AF10: 0 | AG10: 0 | AH10: 1 | AR10: 84 | AS10: 53 | AT10: 6 | AU10: 45 | AV10: 57 | AW10: 234 | AX10: 410 | AY10: 64 | AZ10: 253 | BA10: 149 | BB10: 64 | BC10: 163 | BD10: 167 | BE10: 61 | BF10: 123 | BG10: 49 | BH10: 77 | BJ10: 0 | BK10: 20 | BL10: 21 | BM10: 10 | BN10: 0 | BO10: 1 | BP10: 5 | BQ10: 1 | BR10: 1 | BT10: 54 | BU10: 14 | BW10: 11 | BX10: 2 | BY10: 0 | BZ10: 1 | CA10: 2 | CB10: GA, TN | CC10: 0 | CF10: 9 | CG10: 1400 | CH10: 0 | CI10: 4 | CJ10: 122 | CK10: 220324 | CL10: 124 | CM10: 155017 | CN10: 13 | CO10: 73 | CP10: 85382 | CQ10: 3 | CR10: 850
B11: Alaska | C11: 6 | D11: 50 | E11: 129 | F11: 12 | H11: 1 | I11: 4 | J11: 6 | K11: 1 | L11: 0 | M11: 0 | N11: 0 | O11: 0 | P11: 0 | R11: 0 | T11: 0 | U11: 0 | V11: 0 | W11: 0 | X11: 1 | Y11: 4 | Z11: 4 | AB11: 11 | AC11: 1 | AD11: 0 | AE11: 0 | AF11: 0 | AG11: 0 | AH11: 0 | AJ11: 10 | AK11: 0 | AL11: 0 | AM11: 0 | AN11: 0 | AO11: 0 | AP11: 1 | AR11: 11 | AS11: 9 | AT11: 1 | AU11: 6 | AV11: 4 | AW11: 16 | AX11: 28 | AY11: 5 | AZ11: 19 | BA11: 13 | BB11: 3 | BC11: 8 | BD11: 11 | BE11: 3 | BF11: 6 | BG11: 2 | BH11: 3 | BJ11: 3 | BK11: 6 | BL11: 1 | BM11: 0 | BN11: 0 | BO11: 0 | BP11: 2 | BQ11: 0 | BR11: 0 | BT11: 12 | BU11: 3 | BW11: 3 | BX11: 0 | BY11: 0 | BZ11: 0 | CA11: 0 | CC11: 0 | CF11: 0 | CG11: 61 | CH11: 0 | CI11: 0 | CJ11: 0 | CK11: 0 | CL11: 2 | CM11: 2385 | CN11: 0 | CO11: 2 | CP11: 1513 | CQ11: 0 | CR11: 0
B12: Arizona | C12: 16 | D12: 509 | E12: 1115 | F12: 47 | H12: 5 | I12: 9 | J12: 9 | K12: 23 | L12: 1 | M12: 0 | N12: 0 | O12: 0 | P12: 0 | R12: 5 | T12: 2 | U12: 3 | V12: 2 | W12: 3 | X12: 3 | Y12: 8 | Z12: 6 | AB12: 41 | AC12: 2 | AD12: 3 | AE12: 0 | AF12: 1 | AH12: 0 | AR12: 68 | AS12: 64 | AT12: 11 | AU12: 26 | AV12: 36 | AW12: 137 | AX12: 234 | AY12: 54 | AZ12: 159 | BA12: 100 | BB12: 24 | BC12: 94 | BD12: 92 | BE12: 75 | BF12: 87 | BG12: 34 | BH12: 35 | BJ12: 3 | BK12: 2 | BL12: 14 | BM12: 12 | BN12: 8 | BO12: 8 | BP12: 5 | BQ12: 3 | BR12: 5 | BT12: 38 | BU12: 19 | BW12: 12 | BX12: 4 | BY12: 2 | BZ12: 0 | CA12: 1 | CB12: CA, NE, OK | CC12: 0 | CF12: 7 | CG12: 903 | CI12: 4 | CJ12: 59 | CK12: 78614 | CL12: 96 | CM12: 81253 | CN12: 8 | CO12: 21 | CP12: 12912 | CQ12: 4 | CR12: 1046
B13: Arkansas | C13: 7 | D13: 414 | E13: 913 | F13: 21 | H13: 2 | I13: 1 | J13: 6 | K13: 11 | L13: 1 | M13: 0 | N13: 0 | O13: 0 | P13: 0 | R13: 2 | T13: 2 | U13: 2 | V13: 2 | W13: 2 | X13: 4 | Y13: 7 | Z13: 4 | AB13: 20 | AC13: 1 | AD13: 0 | AE13: 0 | AF13: 0 | AH13: 0 | AR13: 31 | AS13: 55 | AT13: 16 | AU13: 15 | AV13: 42 | AW13: 99 | AX13: 183 | AY13: 37 | AZ13: 166 | BA13: 69 | BB13: 19 | BC13: 99 | BD13: 86 | BE13: 30 | BF13: 73 | BG13: 26 | BH13: 50 | BJ13: 3 | BK13: 5 | BL13: 5 | BM13: 2 | BO13: 4 | BP13: 2 | BQ13: 2 | BR13: 1 | BT13: 21 | BU13: 12 | BW13: 7 | BX13: 2 | BY13: 1 | BZ13: 1 | CA13: 1 | CB13: NY | CC13: 1 | CD13: Saudi Arabia | CF13: 6 | CG13: 851 | CI13: 10 | CJ13: 105 | CK13: 139556 | CL13: 81 | CM13: 148504 | CN13: 7 | CO13: 46 | CP13: 77620 | CQ13: 1 | CR13: 21
B14: California | C14: 82 | D14: 2530 | E14: 6624 | F14: 283 | H14: 44 | I14: 38 | J14: 47 | K14: 150 | L14: 0 | M14: 0 | N14: 0 | O14: 0 | P14: 1 | R14: 22 | T14: 23 | U14: 17 | V14: 15 | W14: 27 | X14: 42 | Y14: 67 | Z14: 31 | AB14: 237 | AC14: 25 | AD14: 14 | AE14: 15 | AF14: 13 | AH14: 17 | AR14: 444 | AS14: 242 | AT14: 43 | AU14: 175 | AV14: 241 | AW14: 900 | AX14: 1373 | AY14: 274 | AZ14: 875 | BA14: 610 | BB14: 227 | BC14: 651 | BD14: 515 | BE14: 332 | BF14: 481 | BG14: 204 | BH14: 346 | BJ14: 0 | BK14: 20 | BL14: 20 | BM14: 89 | BN14: 36 | BO14: 30 | BP14: 72 | BQ14: 10 | BR14: 7 | BT14: 218 | BU14: 75 | BW14: 40 | BX14: 14 | BY14: 3 | BZ14: 1 | CA14: 8 | CB14: AZ, HI(3), ID, MA, MN, NV(2), OH(2), SC, VA | CC14: 8 | CD14: Argentina, Australia, England(2), Germany, Italy, Hong Kong, Mexico(4), Myanamr, Philippines(2), Vancouver-BC | CF14: 15 | CG14: 4885 | CI14: 12 | CJ14: 223 | CK14: 2702074 | CL14: 315 | CM14: 2186819 | CN14: 42 | CO14: 147 | CP14: 1026246 | CQ14: 4 | CR14: 44170
B15: Canada | C15: 9 | D15: 501 | E15: 1222 | F15: 39 | H15: 3 | I15: 4 | J15: 3 | K15: 28 | L15: 0 | M15: 0 | N15: 0 | O15: 0 | P15: 0 | R15: 0 | T15: 0 | U15: 0 | V15: 0 | W15: 0 | X15: 0 | Y15: 5 | Z15: 2 | AB15: 32 | AC15: 3 | AD15: 0 | AE15: 6 | AF15: 0 | AH15: 4 | AR15: 62 | AS15: 64 | AT15: 4 | AU15: 17 | AV15: 38 | AW15: 230 | AX15: 230 | AY15: 46 | AZ15: 170 | BA15: 109 | BB15: 43 | BC15: 107 | BD15: 77 | BE15: 73 | BF15: 72 | BG15: 39 | BH15: 52 | BJ15: 0 | BK15: 6 | BL15: 6 | BM15: 19 | BN15: 3 | BO15: 0 | BP15: 3 | BQ15: 0 | BR15: 0 | BT15: 39 | BU15: 21 | BW15: 9 | BX15: 7 | BY15: 1 | BZ15: 0 | CA15: 0 | CC15: 0 | CF15: 2 | CG15: 971 | CI15: 0 | CJ15: 14 | CK15: 21551 | CL15: 18 | CM15: 47349 | CN15: 2 | CO15: 6 | CP15: 13036 | CQ15: 0 | CR15: 0
B16: Colorado | C16: 16 | D16: 762 | E16: 1558 | F16: 42 | H16: 6 | I16: 5 | J16: 9 | K16: 28 | L16: 1 | M16: 0 | N16: 0 | O16: 0 | P16: 0 | R16: 3 | T16: 2 | U16: 3 | V16: 1 | W16: 0 | X16: 1 | Y16: 13 | Z16: 5 | AB16: 39 | AC16: 2 | AD16: 1 | AE16: 1 | AF16: 3 | AH16: 2 | AR16: 75 | AS16: 51 | AT16: 15 | AU16: 31 | AV16: 64 | AW16: 186 | AX16: 360 | AY16: 92 | AZ16: 252 | BA16: 138 | BB16: 41 | BC16: 143 | BD16: 135 | BE16: 91 | BF16: 106 | BG16: 68 | BH16: 65 | BJ16: 1 | BK16: 4 | BL16: 4 | BM16: 10 | BN16: 3 | BO16: 7 | BP16: 20 | BQ16: 2 | BR16: 1 | BT16: 49 | BU16: 23 | BW16: 12 | BX16: 3 | BY16: 0 | BZ16: 0 | CA16: 2 | CB16: FL, TX | CC16: 1 | CD16: Brussels | CF16: 3 | CG16: 1028 | CI16: 2 | CJ16: 40 | CK16: 59923 | CL16: 69 | CM16: 90533 | CN16: 9 | CO16: 10 | CP16: 3446 | CQ16: 0 | CR16: 0
B17: Connecticut | C17: 2 | D17: 39 | E17: 149 | F17: 8 | H17: 0 | I17: 2 | J17: 3 | K17: 3 | L17: 0 | M17: 0 | N17: 0 | O17: 0 | P17: 0 | R17: 0 | T17: 0 | U17: 0 | V17: 0 | W17: 0 | X17: 0 | Y17: 4 | Z17: 1 | AB17: 5 | AC17: 1 | AD17: 1 | AE17: 0 | AF17: 1 | AG17: 0 | AH17: 0 | AJ17: 3 | AK17: 2 | AL17: 0 | AM17: 0 | AN17: 0 | AO17: 0 | AP17: 0 | AR17: 18 | AS17: 6 | AT17: 1 | AU17: 1 | AV17: 12 | AW17: 20 | AX17: 31 | AY17: 7 | AZ17: 16 | BA17: 17 | BB17: 2 | BC17: 14 | BD17: 11 | BE17: 9 | BF17: 8 | BG17: 5 | BH17: 5 | BJ17: 0 | BK17: 1 | BL17: 6 | BM17: 0 | BN17: 0 | BO17: 0 | BP17: 1 | BQ17: 0 | BR17: 0 | BT17: 8 | BU17: 4 | BW17: 4 | BX17: 0 | BY17: 0 | BZ17: 0 | CA17: 0 | CC17: 0 | CF17: 0 | CG17: 106 | CH17: 0 | CI17: 0 | CJ17: 0 | CK17: 0 | CL17: 1 | CM17: 688 | CN17: 0 | CO17: 0 | CP17: 0 | CQ17: 0 | CR17: 0
B18: Delaware | C18: 0 | D18: 2 | E18: 32 | F18: 2 | H18: 0 | I18: 2 | J18: 1 | K18: 0 | L18: 0 | M18: 0 | N18: 0 | O18: 0 | P18: 0 | R18: 0 | T18: 0 | U18: 0 | V18: 0 | W18: 0 | X18: 0 | Y18: 3 | Z18: 0 | AB18: 1 | AC18: 0 | AD18: 0 | AE18: 0 | AF18: 1 | AH18: 0 | AR18: 2 | AS18: 0 | AT18: 0 | AU18: 0 | AV18: 0 | AW18: 2 | AX18: 8 | AY18: 2 | AZ18: 5 | BA18: 4 | BB18: 0 | BC18: 0 | BD18: 2 | BE18: 1 | BF18: 3 | BG18: 1 | BH18: 1 | BJ18: 0 | BK18: 1 | BL18: 1 | BM18: 0 | BN18: 0 | BO18: 0 | BP18: 1 | BQ18: 0 | BR18: 0 | BT18: 2 | BU18: 0 | BW18: 1 | BX18: 0 | BY18: 0 | BZ18: 0 | CA18: 0 | CC18: 0 | CF18: 0 | CG18: 22 | CI18: 0 | CJ18: 0 | CK18: 0 | CL18: 0 | CM18: 0 | CN18: 0 | CO18: 0 | CP18: 0 | CQ18: 0 | CR18: 0
B19: District of Columbia | C19: 2 | D19: 48 | E19: 133 | F19: 7 | H19: 1 | I19: 0 | J19: 2 | K19: 2 | L19: 1 | M19: 0 | N19: 0 | O19: 0 | P19: 0 | R19: 1 | T19: 1 | U19: 1 | V19: 0 | W19: 1 | X19: 1 | Y19: 3 | Z19: 1 | AB19: 5 | AC19: 2 | AD19: 0 | AE19: 0 | AF19: 1 | AH19: 0 | AR19: 13 | AS19: 6 | AT19: 0 | AU19: 2 | AV19: 2 | AW19: 20 | AX19: 27 | AY19: 2 | AZ19: 4 | BA19: 4 | BB19: 1 | BC19: 15 | BD19: 6 | BE19: 4 | BF19: 7 | BG19: 1 | BH19: 8 | BJ19: 0 | BK19: 0 | BL19: 0 | BM19: 3 | BN19: 2 | BO19: 0 | BP19: 0 | BQ19: 0 | BR19: 0 | BT19: 7 | BU19: 2 | BW19: 1 | BX19: 1 | BY19: 0 | BZ19: 0 | CA19: 2 | CB19: VA | CC19: 0 | CF19: 1 | CG19: 120 | CH19: 0 | CI19: 2 | CJ19: 17 | CK19: 133625 | CL19: 11 | CM19: 53422 | CN19: 10 | CO19: 1 | CP19: 17000 | CQ19: 0 | CR19: 0
B20: Florida | C20: 29 | D20: 898 | E20: 4674 | F20: 189 | H20: 24 | I20: 20 | J20: 49 | K20: 76 | L20: 14 | M20: 4 | N20: 1 | O20: 0 | P20: 0 | R20: 11 | T20: 8 | U20: 5 | V20: 2 | W20: 8 | X20: 7 | Y20: 29 | Z20: 23 | AB20: 152 | AC20: 18 | AD20: 5 | AE20: 0 | AF20: 17 | AH20: 3 | AR20: 297 | AS20: 230 | AT20: 18 | AU20: 106 | AV20: 157 | AW20: 707 | AX20: 947 | AY20: 183 | AZ20: 633 | BA20: 399 | BB20: 105 | BC20: 270 | BD20: 418 | BE20: 258 | BF20: 311 | BG20: 125 | BH20: 182 | BJ20: 0 | BK20: 65 | BL20: 39 | BM20: 21 | BN20: 11 | BO20: 11 | BP20: 41 | BQ20: 8 | BR20: 7 | BT20: 189 | BU20: 86 | BW20: 50 | BX20: 13 | BY20: 6 | BZ20: 0 | CA20: 3 | CB20: AL, DC, GA, IN, KY, MI, NC, VA, WI | CC20: 9 | CD20: Columbia, Costa Rica, Dominican Republic, Guatemala, India, Netherlands, Peru, South Africa, Zimbabwe | CF20: 21 | CG20: 3169 | CH20: 8 | CI20: 7 | CJ20: 209 | CK20: 2967507 | CL20: 260 | CM20: 1411895 | CN20: 30 | CO20: 164 | CP20: 1712030 | CQ20: 6 | CR20: 381273
B21: Georgia | C21: 40 | D21: 1461 | E21: 3338 | F21: 127 | H21: 16 | I21: 9 | J21: 36 | K21: 49 | L21: 9 | M21: 5 | N21: 0 | O21: 0 | P21: 0 | R21: 7 | T21: 4 | U21: 3 | V21: 4 | W21: 4 | X21: 4 | Y21: 12 | Z21: 8 | AB21: 87 | AC21: 36 | AD21: 0 | AE21: 1 | AF21: 3 | AG21: 1 | AH21: 1 | AJ21: 37 | AK21: 26 | AL21: 1 | AM21: 0 | AN21: 0 | AO21: 0 | AP21: 5 | AR21: 211 | AS21: 81 | AT21: 16 | AU21: 79 | AV21: 88 | AW21: 477 | AX21: 692 | AY21: 127 | AZ21: 548 | BA21: 323 | BB21: 94 | BC21: 214 | BD21: 314 | BE21: 158 | BF21: 219 | BG21: 103 | BH21: 151 | BJ21: 0 | BK21: 66 | BL21: 19 | BM21: 21 | BN21: 12 | BO21: 3 | BP21: 5 | BQ21: 3 | BR21: 0 | BT21: 127 | BU21: 41 | BW21: 25 | BX21: 5 | BY21: 1 | BZ21: 0 | CA21: 6 | CB21: CA, DC(2), FL, LA, MO, SC, TN(2), | CC21: 1 | CD21: Australia | CF21: 19 | CG21: 2506 | CH21: 0 | CI21: 14 | CJ21: 177 | CK21: 441400 | CL21: 177 | CM21: 772271 | CN21: 19 | CO21: 96 | CP21: 201298 | CQ21: 2 | CR21: 631
B22: Hawaii | C22: 3 | D22: 56 | E22: 133 | F22: 10 | H22: 2 | I22: 0 | J22: 4 | K22: 3 | L22: 0 | M22: 0 | N22: 0 | O22: 0 | P22: 0 | R22: 2 | T22: 2 | U22: 1 | V22: 1 | W22: 1 | X22: 2 | Y22: 4 | Z22: 3 | AB22: 8 | AC22: 0 | AD22: 1 | AE22: 1 | AF22: 1 | AG22: 0 | AH22: 1 | AJ22: 1 | AK22: 0 | AL22: 0 | AM22: 0 | AN22: 0 | AO22: 1 | AP22: 0 | AR22: 13 | AS22: 12 | AT22: 1 | AU22: 3 | AV22: 2 | AW22: 32 | AX22: 22 | AY22: 3 | AZ22: 12 | BA22: 7 | BB22: 6 | BC22: 11 | BD22: 9 | BE22: 5 | BF22: 8 | BG22: 1 | BH22: 13 | BJ22: 0 | BK22: 1 | BL22: 3 | BM22: 3 | BN22: 2 | BO22: 0 | BP22: 1 | BQ22: 1 | BR22: 0 | BT22: 8 | BU22: 6 | BW22: 0 | BX22: 3 | BY22: 0 | BZ22: 1 | CA22: 1 | CB22: AZ, CA | CC22: 1 | CD22: Japan | CF22: 0 | CG22: 36 | CH22: 0 | CI22: 0 | CJ22: 3 | CK22: 4299 | CL22: 3 | CM22: 1282 | CN22: 1 | CO22: 1 | CP22: 337 | CQ22: 0 | CR22: 0
B23: Idaho | C23: 5 | D23: 152 | E23: 277 | F23: 16 | H23: 0 | I23: 7 | J23: 4 | K23: 5 | L23: 0 | M23: 0 | N23: 0 | O23: 0 | P23: 0 | R23: 0 | T23: 1 | U23: 0 | V23: 0 | W23: 0 | X23: 2 | Y23: 6 | Z23: 1 | AB23: 16 | AC23: 0 | AD23: 0 | AE23: 1 | AF23: 0 | AG23: 0 | AH23: 1 | AJ23: 0 | AK23: 0 | AL23: 0 | AM23: 0 | AN23: 0 | AO23: 0 | AP23: 0 | AR23: 26 | AS23: 12 | AT23: 0 | AU23: 11 | AV23: 18 | AW23: 46 | AX23: 39 | AY23: 9 | AZ23: 42 | BA23: 31 | BB23: 5 | BC23: 25 | BD23: 20 | BE23: 11 | BF23: 13 | BG23: 6 | BH23: 5 | BJ23: 2 | BK23: 2 | BL23: 4 | BM23: 1 | BN23: 1 | BO23: 0 | BP23: 6 | BQ23: 0 | BR23: 0 | BT23: 16 | BU23: 7 | BW23: 6 | BX23: 1 | BY23: 0 | BZ23: 0 | CA23: 0 | CC23: 0 | CF23: 0 | CG23: 107 | CH23: 0 | CI23: 0 | CJ23: 1 | CK23: 2037 | CL23: 1 | CM23: 1534 | CN23: 1 | CO23: 0 | CP23: 0 | CQ23: 0 | CR23: 0
B24: Illinois | C24: 25 | D24: 915 | E24: 1957 | F24: 73 | H24: 13 | I24: 6 | J24: 20 | K24: 18 | L24: 13 | M24: 3 | N24: 1 | O24: 0 | P24: 0 | R24: 5 | T24: 4 | U24: 2 | V24: 2 | W24: 6 | X24: 9 | Y24: 21 | Z24: 6 | AB24: 63 | AC24: 16 | AD24: 1 | AE24: 0 | AF24: 2 | AG24: 0 | AH24: 8 | AJ24: 108 | AK24: 14 | AL24: 15 | AM24: 2 | AN24: 1 | AO24: 0 | AP24: 11 | AR24: 119 | AS24: 164 | AT24: 13 | AU24: 53 | AV24: 69 | AW24: 255 | AX24: 392 | AY24: 109 | AZ24: 281 | BA24: 200 | BB24: 57 | BC24: 167 | BD24: 172 | BE24: 104 | BF24: 131 | BG24: 72 | BH24: 75 | BJ24: 1 | BK24: 11 | BL24: 26 | BM24: 10 | BN24: 12 | BO24: 2 | BP24: 11 | BQ24: 3 | BR24: 0 | BT24: 73 | BU24: 35 | BW24: 21 | BX24: 11 | BY24: 2 | BZ24: 1 | CA24: 3 | CB24: FL, GA, IN | CC24: 0 | CF24: 6 | CG24: 1544 | CH24: 2 | CI24: 1 | CJ24: 47 | CK24: 51774 | CL24: 109 | CM24: 127956 | CN24: 6 | CO24: 11 | CP24: 43020 | CQ24: 0 | CR24: 0
B25: Indiana | C25: 14 | D25: 785 | E25: 1991 | F25: 59 | H25: 6 | I25: 3 | J25: 14 | K25: 22 | L25: 11 | M25: 2 | N25: 0 | O25: 0 | P25: 0 | R25: 1 | T25: 2 | U25: 0 | V25: 0 | W25: 1 | X25: 3 | Y25: 10 | Z25: 6 | AB25: 53 | AC25: 5 | AD25: 1 | AE25: 0 | AF25: 0 | AG25: 1 | AH25: 1 | AR25: 94 | AS25: 52 | AT25: 9 | AU25: 38 | AV25: 88 | AW25: 224 | AX25: 484 | AY25: 66 | AZ25: 336 | BA25: 177 | BB25: 21 | BC25: 155 | BD25: 176 | BE25: 141 | BF25: 156 | BG25: 49 | BH25: 77 | BJ25: 1 | BK25: 10 | BL25: 16 | BM25: 15 | BN25: 6 | BO25: 3 | BP25: 9 | BQ25: 2 | BR25: 2 | BT25: 59 | BU25: 26 | BW25: 11 | BX25: 5 | BY25: 1 | BZ25: 0 | CA25: 1 | CB25: KY | CC25: 0 | CF25: 4 | CG25: 1473 | CH25: 2 | CI25: 5 | CJ25: 104 | CK25: 349953 | CL25: 93 | CM25: 129854 | CN25: 15 | CO25: 32 | CP25: 39096 | CQ25: 0 | CR25: 0
B26: Iowa | C26: 3 | D26: 223 | E26: 441 | F26: 10 | H26: 1 | I26: 4 | J26: 2 | K26: 5 | L26: 3 | M26: 0 | N26: 0 | O26: 0 | P26: 0 | R26: 0 | T26: 0 | U26: 0 | V26: 0 | W26: 0 | X26: 0 | Y26: 4 | Z26: 2 | AB26: 14 | AC26: 0 | AD26: 0 | AE26: 0 | AF26: 1 | AH26: 0 | AR26: 22 | AS26: 22 | AT26: 7 | AU26: 10 | AV26: 16 | AW26: 73 | AX26: 91 | AY26: 17 | AZ26: 56 | BA26: 42 | BB26: 27 | BC26: 29 | BD26: 30 | BE26: 20 | BF26: 31 | BG26: 12 | BH26: 19 | BJ26: 0 | BK26: 2 | BL26: 10 | BM26: 0 | BN26: 0 | BO26: 1 | BP26: 2 | BQ26: 1 | BR26: 1 | BT26: 15 | BU26: 7 | BW26: 3 | BX26: 2 | BY26: 0 | BZ26: 0 | CA26: 1 | CB26: MN | CC26: 0 | CF26: 2 | CG26: 318 | CI26: 0 | CJ26: 19 | CK26: 6473 | CL26: 27 | CM26: 27401 | CN26: 0 | CO26: 0 | CP26: 0 | CQ26: 0 | CR26: 0
B27: Kansas | C27: 4 | D27: 170 | E27: 454 | F27: 19 | H27: 3 | I27: 1 | J27: 7 | K27: 7 | L27: 2 | M27: 0 | N27: 0 | O27: 0 | P27: 0 | R27: 1 | T27: 1 | U27: 1 | V27: 0 | W27: 0 | X27: 1 | Y27: 5 | Z27: 2 | AB27: 18 | AC27: 1 | AD27: 0 | AE27: 0 | AF27: 1 | AH27: 0 | AR27: 30 | AS27: 21 | AT27: 5 | AU27: 11 | AV27: 17 | AW27: 58 | AX27: 118 | AY27: 21 | AZ27: 66 | BA27: 33 | BB27: 11 | BC27: 32 | BD27: 31 | BE27: 20 | BF27: 40 | BG27: 17 | BH27: 20 | BJ27: 0 | BK27: 1 | BL27: 6 | BM27: 4 | BN27: 2 | BO27: 0 | BP27: 7 | BQ27: 0 | BR27: 0 | BT27: 19 | BU27: 8 | BW27: 5 | BX27: 2 | BY27: 0 | BZ27: 0 | CA27: 0 | CC27: 0 | CF27: 3 | CG27: 351 | CI27: 1 | CJ27: 27 | CK27: 80703 | CL27: 36 | CM27: 25365 | CN27: 2 | CO27: 18 | CP27: 9619 | CQ27: 0 | CR27: 0
B28: Kentucky | C28: 12 | D28: 274 | E28: 602 | F28: 28 | H28: 5 | I28: 6 | J28: 9 | K28: 8 | L28: 0 | M28: 1 | N28: 0 | O28: 0 | P28: 0 | R28: 2 | T28: 1 | U28: 2 | V28: 1 | W28: 1 | X28: 2 | Y28: 8 | Z28: 2 | AB28: 24 | AC28: 3 | AD28: 0 | AE28: 0 | AF28: 0 | AH28: 1 | AR28: 45 | AS28: 28 | AT28: 6 | AU28: 19 | AV28: 17 | AW28: 64 | AX28: 127 | AY28: 23 | AZ28: 78 | BA28: 63 | BB28: 9 | BC28: 62 | BD28: 53 | BE28: 31 | BF28: 40 | BG28: 12 | BH28: 36 | BJ28: 0 | BK28: 9 | BL28: 9 | BM28: 2 | BN28: 3 | BO28: 2 | BP28: 4 | BQ28: 2 | BR28: 0 | BT28: 28 | BU28: 10 | BW28: 7 | BX28: 2 | BY28: 2 | BZ28: 0 | CA28: 2 | CB28: IN | CC28: 0 | CF28: 6 | CG28: 498 | CI28: 6 | CJ28: 82 | CK28: 66598 | CL28: 48 | CM28: 42987 | CN28: 3 | CO28: 8 | CP28: 7110 | CQ28: 0 | CR28: 0
B29: Louisiana | C29: 5 | D29: 290 | E29: 720 | F29: 33 | H29: 5 | I29: 4 | J29: 10 | K29: 15 | L29: 1 | M29: 0 | N29: 0 | O29: 0 | P29: 0 | R29: 2 | T29: 2 | U29: 1 | V29: 0 | W29: 2 | X29: 2 | Y29: 7 | Z29: 2 | AB29: 30 | AC29: 4 | AD29: 0 | AE29: 0 | AF29: 1 | AH29: 0 | AR29: 55 | AS29: 30 | AT29: 2 | AU29: 21 | AV29: 32 | AW29: 64 | AX29: 153 | AY29: 20 | AZ29: 111 | BA29: 68 | BB29: 35 | BC29: 57 | BD29: 76 | BE29: 23 | BF29: 46 | BG29: 12 | BH29: 29 | BJ29: 0 | BK29: 13 | BL29: 11 | BM29: 2 | BN29: 5 | BO29: 1 | BP29: 3 | BQ29: 0 | BR29: 0 | BT29: 33 | BU29: 12 | BW29: 5 | BX29: 3 | BY29: 2 | BZ29: 0 | CA29: 1 | CB29: GA, MS(2), TX | CC29: 6 | CD29: Costa Rica, Eswatini, Honduras, Mozambique, Puerto Rico, Spain, | CF29: 7 | CG29: 560 | CI29: 1 | CJ29: 45 | CK29: 48884 | CL29: 91 | CM29: 143963 | CN29: 5 | CO29: 36 | CP29: 23829 | CQ29: 0 | CR29: 0
B30: Maine | C30: 0 | D30: 13 | E30: 20 | F30: 1 | H30: 0 | I30: 0 | J30: 0 | K30: 1 | L30: 0 | M30: 0 | N30: 0 | O30: 0 | P30: 0 | R30: 0 | T30: 0 | U30: 0 | V30: 0 | W30: 0 | X30: 0 | Y30: 1 | Z30: 0 | AB30: 1 | AC30: 0 | AD30: 0 | AE30: 0 | AF30: 0 | AH30: 1 | AR30: 1 | AS30: 0 | AT30: 0 | AU30: 2 | AV30: 0 | AW30: 3 | AX30: 2 | AY30: 0 | AZ30: 2 | BA30: 1 | BB30: 1 | BC30: 3 | BD30: 1 | BE30: 2 | BF30: 2 | BG30: 0 | BH30: 1 | BJ30: 0 | BK30: 0 | BL30: 0 | BM30: 0 | BN30: 0 | BO30: 0 | BP30: 1 | BQ30: 0 | BR30: 0 | BT30: 1 | BU30: 0 | BW30: 0 | BX30: 0 | BY30: 0 | BZ30: 0 | CA30: 0 | CC30: 0 | CF30: 0 | CG30: 0 | CI30: 0 | CJ30: 0 | CK30: 0 | CL30: 0 | CM30: 0 | CN30: 0 | CO30: 0 | CP30: 0 | CQ30: 0 | CR30: 0
B31: Maryland | C31: 10 | D31: 243 | E31: 686 | F31: 45 | H31: 14 | I31: 4 | J31: 11 | K31: 9 | L31: 1 | M31: 0 | N31: 0 | O31: 0 | P31: 0 | R31: 1 | T31: 2 | U31: 1 | V31: 1 | W31: 3 | X31: 3 | Y31: 3 | Z31: 2 | AB31: 16 | AC31: 20 | AD31: 0 | AE31: 2 | AF31: 3 | AH31: 2 | AR31: 61 | AS31: 23 | AT31: 5 | AU31: 11 | AV31: 28 | AW31: 92 | AX31: 168 | AY31: 29 | AZ31: 69 | BA31: 54 | BB31: 19 | BC31: 73 | BD31: 59 | BE31: 37 | BF31: 43 | BG31: 25 | BH31: 30 | BJ31: 3 | BK31: 3 | BL31: 12 | BM31: 11 | BN31: 5 | BO31: 2 | BP31: 8 | BQ31: 1 | BR31: 1 | BT31: 45 | BU31: 13 | BW31: 7 | BX31: 2 | BY31: 0 | BZ31: 0 | CA31: 2 | CB31: NC(2), VA | CC31: 0 | CF31: 1 | CG31: 350 | CI31: 3 | CJ31: 15 | CK31: 115314 | CL31: 19 | CM31: 225290 | CN31: 4 | CO31: 8 | CP31: 7738 | CQ31: 1 | CR31: 468
B32: Mass | C32: 6 | D32: 92 | E32: 201 | F32: 11 | H32: 3 | I32: 0 | J32: 1 | K32: 4 | L32: 1 | M32: 0 | N32: 0 | O32: 0 | P32: 0 | R32: 0 | T32: 0 | U32: 0 | V32: 0 | W32: 0 | X32: 0 | Y32: 3 | Z32: 0 | AB32: 8 | AC32: 4 | AD32: 0 | AE32: 0 | AF32: 0 | AG32: 0 | AH32: 1 | AJ32: 1 | AK32: 2 | AL32: 0 | AM32: 0 | AN32: 0 | AO32: 0 | AP32: 1 | AR32: 17 | AS32: 6 | AT32: 0 | AU32: 4 | AV32: 5 | AW32: 39 | AX32: 41 | AY32: 12 | AZ32: 20 | BA32: 17 | BB32: 3 | BC32: 12 | BD32: 24 | BE32: 7 | BF32: 13 | BG32: 11 | BH32: 12 | BJ32: 0 | BK32: 2 | BL32: 3 | BM32: 2 | BN32: 1 | BO32: 0 | BP32: 3 | BQ32: 0 | BR32: 0 | BT32: 11 | BU32: 4 | BW32: 3 | BX32: 0 | BY32: 0 | BZ32: 0 | CA32: 0 | CC32: 0 | CF32: 2 | CG32: 148 | CH32: 0 | CI32: 0 | CJ32: 4 | CK32: 3437 | CL32: 18 | CM32: 21493 | CN32: 0 | CO32: 6 | CP32: 7115 | CQ32: 0 | CR32: 0
B33: Michigan | C33: 12 | D33: 482 | E33: 1285 | F33: 59 | H33: 15 | I33: 3 | J33: 15 | K33: 18 | L33: 7 | M33: 0 | N33: 0 | O33: 0 | P33: 0 | R33: 1 | T33: 1 | U33: 0 | V33: 0 | W33: 1 | X33: 1 | Y33: 10 | Z33: 3 | AB33: 40 | AC33: 17 | AD33: 0 | AE33: 0 | AF33: 5 | AH33: 2 | AR33: 90 | AS33: 50 | AT33: 4 | AU33: 39 | AV33: 58 | AW33: 151 | AX33: 302 | AY33: 52 | AZ33: 188 | BA33: 136 | BB33: 33 | BC33: 129 | BD33: 104 | BE33: 58 | BF33: 68 | BG33: 42 | BH33: 52 | BJ33: 0 | BK33: 4 | BL33: 21 | BM33: 11 | BN33: 9 | BO33: 4 | BP33: 10 | BQ33: 2 | BR33: 2 | BT33: 59 | BU33: 19 | BW33: 6 | BX33: 8 | BY33: 1 | BZ33: 0 | CA33: 1 | CB33: TX | CC33: 2 | CD33: China, Indonesia | CF33: 1 | CG33: 851 | CI33: 3 | CJ33: 37 | CK33: 37039 | CL33: 65 | CM33: 91056 | CN33: 14 | CO33: 22 | CP33: 44370 | CQ33: 8 | CR33: 2126
B34: Minnesota | C34: 11 | D34: 347 | E34: 1508 | F34: 29 | H34: 0 | I34: 2 | J34: 7 | K34: 15 | L34: 4 | M34: 3 | N34: 0 | O34: 0 | P34: 0 | R34: 2 | T34: 2 | U34: 1 | V34: 1 | W34: 2 | X34: 3 | Y34: 8 | Z34: 3 | AB34: 26 | AC34: 1 | AD34: 0 | AE34: 0 | AF34: 3 | AH34: 4 | AR34: 45 | AS34: 56 | AT34: 8 | AU34: 16 | AV34: 67 | AW34: 142 | AX34: 345 | AY34: 69 | AZ34: 245 | BA34: 134 | BB34: 18 | BC34: 134 | BD34: 120 | BE34: 94 | BF34: 102 | BG34: 56 | BH34: 57 | BJ34: 0 | BK34: 3 | BL34: 7 | BM34: 11 | BN34: 4 | BO34: 1 | BP34: 8 | BQ34: 1 | BR34: 0 | BT34: 27 | BU34: 17 | BW34: 14 | BX34: 4 | BY34: 1 | BZ34: 0 | CA34: 0 | CC34: 2 | CD34: Canada, Eswatini, Mexico | CF34: 4 | CG34: 1296 | CI34: 1 | CJ34: 22 | CK34: 93701 | CL34: 42 | CM34: 273473 | CN34: 9 | CO34: 21 | CP34: 38190 | CQ34: 1 | CR34: 2000
B35: Mississippi | C35: 5 | D35: 229 | E35: 459 | F35: 17 | H35: 1 | I35: 0 | J35: 7 | K35: 7 | L35: 1 | M35: 0 | N35: 0 | O35: 0 | P35: 0 | R35: 1 | T35: 1 | U35: 0 | V35: 0 | W35: 1 | X35: 1 | Y35: 3 | Z35: 1 | AB35: 13 | AC35: 1 | AD35: 0 | AE35: 0 | AF35: 2 | AH35: 0 | AR35: 32 | AS35: 15 | AT35: 1 | AU35: 12 | AV35: 18 | AW35: 43 | AX35: 66 | AY35: 19 | AZ35: 80 | BA35: 51 | BB35: 26 | BC35: 53 | BD35: 51 | BE35: 17 | BF35: 20 | BG35: 18 | BH35: 26 | BJ35: 0 | BK35: 8 | BL35: 4 | BM35: 2 | BN35: 0 | BO35: 1 | BP35: 3 | BQ35: 0 | BR35: 0 | BT35: 17 | BU35: 6 | BW35: 1 | BX35: 3 | BY35: 0 | BZ35: 0 | CA35: 0 | CC35: 0 | CF35: 3 | CG35: 397 | CI35: 0 | CJ35: 52 | CK35: 32656 | CL35: 79 | CM35: 100406 | CN35: 0 | CO35: 16 | CP35: 8662 | CQ35: 0 | CR35: 0
B36: Missouri | C36: 13 | D36: 635 | E36: 1577 | F36: 60 | H36: 10 | I36: 7 | J36: 13 | K36: 27 | L36: 6 | M36: 1 | N36: 0 | O36: 0 | P36: 0 | R36: 4 | T36: 4 | U36: 4 | V36: 3 | W36: 2 | X36: 5 | Y36: 9 | Z36: 4 | AB36: 60 | AC36: 3 | AD36: 0 | AE36: 1 | AF36: 1 | AH36: 2 | AR36: 91 | AS36: 54 | AT36: 11 | AU36: 25 | AV36: 77 | AW36: 148 | AX36: 358 | AY36: 54 | AZ36: 217 | BA36: 152 | BB36: 49 | BC36: 146 | BD36: 121 | BE36: 95 | BF36: 160 | BG36: 47 | BH36: 64 | BJ36: 3 | BK36: 13 | BL36: 17 | BM36: 8 | BN36: 4 | BO36: 1 | BP36: 14 | BQ36: 1 | BR36: 0 | BT36: 60 | BU36: 28 | BW36: 20 | BX36: 1 | BY36: 0 | BZ36: 1 | CA36: 5 | CB36: FL(3), IA(2), IL(3), KS, KY, MI(2) | CC36: 0 | CF36: 6 | CG36: 1086 | CI36: 2 | CJ36: 38 | CK36: 254535 | CL36: 82 | CM36: 457167 | CN36: 12 | CO36: 22 | CP36: 48603 | CQ36: 6 | CR36: 28612
B37: Montana | C37: 2 | D37: 34 | E37: 65 | F37: 4 | H37: 0 | I37: 0 | J37: 1 | K37: 3 | L37: 0 | M37: 0 | N37: 0 | O37: 0 | P37: 0 | R37: 2 | T37: 2 | U37: 1 | V37: 1 | W37: 3 | X37: 1 | Y37: 2 | Z37: 3 | AB37: 4 | AC37: 0 | AD37: 0 | AE37: 0 | AF37: 0 | AG37: 0 | AH37: 0 | AJ37: 1 | AK37: 0 | AL37: 0 | AM37: 0 | AN37: 0 | AO37: 0 | AP37: 0 | AR37: 5 | AS37: 3 | AT37: 0 | AU37: 1 | AV37: 3 | AW37: 4 | AX37: 13 | AY37: 7 | AZ37: 10 | BA37: 6 | BB37: 5 | BC37: 6 | BD37: 2 | BE37: 3 | BF37: 3 | BG37: 7 | BH37: 3 | BJ37: 0 | BK37: 0 | BL37: 1 | BM37: 1 | BN37: 0 | BO37: 0 | BP37: 2 | BQ37: 0 | BR37: 0 | BT37: 3 | BU37: 4 | BW37: 1 | BX37: 1 | BY37: 1 | BZ37: 0 | CA37: 1 | CB37: ID, OR, UT, WY | CC37: 0 | CF37: 1 | CG37: 50 | CH37: 0 | CI37: 0 | CJ37: 4 | CK37: 54724 | CL37: 4 | CM37: 121006 | CN37: 0 | CO37: 0 | CP37: 0 | CQ37: 0 | CR37: 0
B38: Nebraska | C38: 3 | D38: 239 | E38: 443 | F38: 11 | H38: 0 | I38: 1 | J38: 5 | K38: 2 | L38: 2 | M38: 1 | N38: 0 | O38: 0 | P38: 0 | R38: 0 | T38: 0 | U38: 0 | V38: 0 | W38: 0 | X38: 0 | Y38: 3 | Z38: 0 | AB38: 11 | AC38: 0 | AD38: 0 | AE38: 0 | AF38: 0 | AH38: 0 | AR38: 19 | AS38: 10 | AT38: 1 | AU38: 11 | AV38: 22 | AW38: 65 | AX38: 106 | AY38: 22 | AZ38: 51 | BA38: 45 | BB38: 22 | BC38: 40 | BD38: 38 | BE38: 22 | BF38: 28 | BG38: 15 | BH38: 23 | BJ38: 0 | BK38: 0 | BL38: 4 | BM38: 1 | BN38: 1 | BO38: 0 | BP38: 5 | BQ38: 0 | BR38: 0 | BT38: 11 | BU38: 4 | BW38: 3 | BX38: 1 | BY38: 0 | BZ38: 0 | CA38: 0 | CC38: 1 | CD38: Serbia(3) | CF38: 0 | CG38: 388 | CI38: 0 | CJ38: 1 | CK38: 12400 | CL38: 0 | CM38: 0 | CN38: 0 | CO38: 0 | CP38: 0 | CQ38: 0 | CR38: 0
B39: Nevada | C39: 6 | D39: 205 | E39: 445 | F39: 18 | H39: 3 | I39: 2 | J39: 3 | K39: 5 | L39: 3 | M39: 0 | N39: 0 | O39: 0 | P39: 0 | R39: 2 | T39: 2 | U39: 1 | V39: 1 | W39: 3 | X39: 2 | Y39: 6 | Z39: 4 | AB39: 15 | AC39: 1 | AD39: 1 | AE39: 0 | AF39: 1 | AH39: 2 | AR39: 34 | AS39: 22 | AT39: 2 | AU39: 13 | AV39: 15 | AW39: 58 | AX39: 117 | AY39: 14 | AZ39: 50 | BA39: 29 | BB39: 7 | BC39: 38 | BD39: 38 | BE39: 25 | BF39: 30 | BG39: 9 | BH39: 17 | BJ39: 0 | BK39: 2 | BL39: 7 | BM39: 1 | BN39: 3 | BO39: 1 | BP39: 4 | BQ39: 1 | BR39: 1 | BT39: 18 | BU39: 9 | BW39: 4 | BX39: 1 | BY39: 1 | BZ39: 0 | CA39: 1 | CC39: 2 | CD39: Australia, Mexico | CF39: 4 | CG39: 303 | CI39: 3 | CJ39: 28 | CK39: 132939 | CL39: 32 | CM39: 90592 | CN39: 4 | CO39: 9 | CP39: 19652 | CQ39: 0 | CR39: 0
B40: New Hampshire | C40: 3 | D40: 45 | E40: 68 | F40: 4 | H40: 0 | I40: 2 | J40: 0 | K40: 1 | L40: 0 | M40: 0 | N40: 0 | O40: 0 | P40: 0 | R40: 0 | T40: 0 | U40: 0 | V40: 0 | W40: 0 | X40: 0 | Y40: 2 | Z40: 1 | AB40: 4 | AC40: 0 | AD40: 0 | AE40: 0 | AF40: 0 | AG40: 0 | AH40: 0 | AJ40: 14 | AK40: 0 | AL40: 0 | AM40: 0 | AN40: 0 | AO40: 0 | AP40: 0 | AR40: 6 | AS40: 14 | AT40: 0 | AU40: 2 | AV40: 1 | AW40: 12 | AX40: 8 | AY40: 2 | AZ40: 6 | BA40: 5 | BB40: 4 | BC40: 3 | BD40: 5 | BE40: 3 | BF40: 5 | BG40: 2 | BH40: 5 | BJ40: 0 | BK40: 1 | BL40: 0 | BM40: 0 | BN40: 0 | BO40: 0 | BP40: 2 | BQ40: 0 | BR40: 0 | BT40: 4 | BU40: 2 | BW40: 1 | BX40: 0 | BY40: 1 | BZ40: 0 | CA40: 1 | CC40: 0 | CF40: 1 | CG40: 55 | CH40: 0 | CI40: 0 | CJ40: 5 | CK40: 2021 | CL40: 7 | CM40: 7683 | CN40: 1 | CO40: 4 | CP40: 1597 | CQ40: 1 | CR40: 195
B41: New Jersey | C41: 4 | D41: 128 | E41: 420 | F41: 27 | H41: 6 | I41: 3 | J41: 6 | K41: 11 | L41: 0 | M41: 0 | N41: 0 | O41: 0 | P41: 0 | R41: 1 | T41: 1 | U41: 2 | V41: 1 | W41: 1 | X41: 1 | Y41: 5 | Z41: 2 | AB41: 14 | AC41: 10 | AD41: 0 | AE41: 2 | AF41: 1 | AH41: 0 | AR41: 36 | AS41: 23 | AT41: 3 | AU41: 6 | AV41: 15 | AW41: 66 | AX41: 83 | AY41: 21 | AZ41: 54 | BA41: 41 | BB41: 11 | BC41: 39 | BD41: 34 | BE41: 8 | BF41: 22 | BG41: 16 | BH41: 19 | BJ41: 0 | BK41: 5 | BL41: 8 | BM41: 5 | BN41: 2 | BO41: 1 | BP41: 6 | BQ41: 1 | BR41: 1 | BT41: 27 | BU41: 7 | BW41: 7 | BX41: 2 | BY41: 0 | BZ41: 0 | CA41: 2 | CB41: GA,PA | CC41: 0 | CF41: 1 | CG41: 254 | CI41: 2 | CJ41: 10 | CK41: 18983 | CL41: 11 | CM41: 11252 | CN41: 7 | CO41: 4 | CP41: 2885 | CQ41: 1 | CR41: 1007
B42: New Mexico | C42: 0 | D42: 19 | E42: 218 | F42: 5 | H42: 0 | I42: 2 | J42: 0 | K42: 3 | L42: 0 | M42: 1 | N42: 0 | O42: 0 | P42: 0 | R42: 1 | T42: 1 | U42: 1 | V42: 1 | W42: 1 | X42: 1 | Y42: 2 | Z42: 1 | AB42: 4 | AC42: 0 | AD42: 0 | AE42: 0 | AF42: 1 | AH42: 0 | AR42: 8 | AS42: 4 | AT42: 0 | AU42: 0 | AV42: 3 | AW42: 41 | AX42: 65 | AY42: 8 | AZ42: 31 | BA42: 11 | BB42: 4 | BC42: 15 | BD42: 13 | BE42: 19 | BF42: 28 | BG42: 4 | BH42: 8 | BJ42: 0 | BK42: 1 | BL42: 0 | BM42: 0 | BN42: 0 | BO42: 3 | BP42: 1 | BQ42: 2 | BR42: 0 | BT42: 5 | BU42: 3 | BW42: 1 | BX42: 0 | BY42: 0 | BZ42: 0 | CA42: 0 | CC42: 0 | CF42: 1 | CG42: 28 | CI42: 0 | CJ42: 0 | CK42: 0 | CL42: 0 | CM42: 0 | CN42: 0 | CO42: 0 | CP42: 0 | CQ42: 0 | CR42: 0
...
